Workbook

Sheet Lisez-moi
A1: Veille procédures collectives — transférabilité vers le Mali
A2: ABACUS RH · généré le | B2: =TEXT(TODAY(),"DD/MM/YYYY") -> 30/08/2026
A4: PÉRIMÈTRE DEMANDÉ | B4: Entreprises françaises sous procédure collective (sauvegarde, redressement, liquidation) dans cinq secteurs : transport & logistique ; fabrication de matériel électrique ; fabrication de machines-outils ; transformation plastique ; fabrication de médicaments génériques. Objectif : identifier celles dont l'activité ou les actifs pourraient être transférés au Mali.
A6: CE QUE CONTIENT CE FICHIER | B6: Un échantillon de 11 dossiers réellement sourcés, chacun accompagné de son lien de presse ou de base publique, noté sur la grille de transférabilité. Plus le référentiel complet (37 codes NAF, 7 critères pondérés) et un modèle de saisie pour l'alimenter.
A8: CE QU'IL NE CONTIENT PAS | B8: La liste exhaustive. Elle est impossible à produire depuis cet environnement : le proxy réseau bloque le BODACC, l'INPI, l'API recherche-entreprises et Gaïa (gaia.abacus-rh.com). Seule la recherche web généraliste répond, et elle remonte des articles de presse, pas un extrait de registre. L'ordre de grandeur réel : le seul secteur transport compte 857 défaillances au T1 2026 (+12,9 %) et plus de 1 900 dossiers actifs fin mars 2026 — l'échantillon ci-contre en couvre une fraction infime.
A10: COMMENT OBTENIR L'EXHAUSTIF | B10: Le script collecte_bodacc.py, livré à côté de ce fichier, interroge l'API BODACC Open Data, filtre sur les 37 codes NAF et régénère ce classeur complet. Il est prêt à tourner : il suffit de l'exécuter depuis le VPS ABACUS ou toute machine dont le réseau n'est pas restreint, ou d'ajouter les domaines à l'allowlist de l'environnement Claude Code.
A12: FIABILITÉ DES DONNÉES | B12: Chaque ligne porte une colonne « Fiabilité source ». Un seul dossier (Mécanique Gaillonnaise de Précision) dispose d'un SIREN et d'une date de jugement confirmés ; les autres reposent sur la presse, avec des effectifs et des dates parfois approximatifs. « n.d. » signifie non disponible et n'a jamais été comblé par une estimation. Aucune donnée de ce fichier n'est inventée : vérifiez chaque dossier au registre avant toute offre de reprise.
A14: EXCLUSIONS ASSUMÉES | B14: Duralex (redressement judiciaire du 01/06/2026, 243 salariés, Orléans) revient dans toutes les recherches mais relève de la verrerie, hors des cinq secteurs demandés. Fibre Excellence (pâte à papier) de même. Ni l'un ni l'autre n'a été retenu.
A16: LECTURE DES SCORES | B16: Score de 1 à 5, moyenne pondérée des 7 critères de l'onglet « Grille Mali ». Classe A (>= 4) : à instruire en priorité. Classe B (>= 3) : à étudier. Classe C (>= 2) : marginal. Classe D (< 2) : non pertinent. Les notes sont des hypothèses sectorielles, pas des mesures — elles sont en bleu et destinées à être ajustées dossier par dossier.
A18: CODE COULEUR | B18: Bleu = cellule de saisie, modifiable. Noir = formule ou texte, ne pas écraser. Fond orangé = point de vigilance.
A20: AVERTISSEMENT JURIDIQUE | B20: Une reprise en plan de cession se joue devant le tribunal de commerce, dans un délai d'offre court (4 mois à compter de l'ouverture, souvent moins). Le transfert d'actifs hors de France peut se heurter au maintien de l'emploi, critère légal de sélection des offres, et à un contrôle des investissements étrangers sur les actifs sensibles — la pharmacie en particulier. À valider avec un conseil avant tout engagement.

Sheet Cas identifiés
A1: Secteur | B1: Raison sociale | C1: SIREN | D1: Localisation | E1: Effectif | F1: CA (EUR) | G1: Procédure | H1: Date jugement | I1: Statut / échéance | J1: Actifs industriels | K1: Source (URL) | L1: Fiabilité source | M1: C1 | N1: C2 | O1: C3 | P1: C4 | Q1: C5 | R1: C6 | S1: C7 | T1: Score /5 | U1: Classe | V1: Commentaire transfert Mali
A2: Transport & logistique | B2: Ziegler France (et sa filiale Satra) | C2: n.d. | D2: Lille (59) — tribunal de commerce de Lille | E2: 1500 | F2: n.d. | G2: Liquidation judiciaire | H2: n.d. (2026) | I2: Liquidation prononcée — environ 1 500 emplois concernés | J2: Flotte poids lourds, agences, plateformes d'entreposage | K2: https://trans.info/fr/faillites-transport-france-2026-ziegler-pedretti-crise-468940 | L2: Presse spécialisée | M2: 4 | N2: 5 | O2: 4 | P2: 5 | Q2: 5 | R2: 4 | S2: 3 | T2: =IF(COUNT(M2:S2)<7,"",SUMPRODUCT(M2:S2,'Grille Mali'!$C$14:$I$14)) -> 4.45 | U2: =IF(NOT(ISNUMBER(T2)),"",IF(T2>=4,"A — Prioritaire",IF(T2>=3,"B — À étudier",IF(T2>=2,"C — Marginal","D — Non pertinent")))) -> A — Prioritaire | V2: Le plus gros gisement d'actifs roulants de l'échantillon. Des tracteurs et remorques devenus non conformes ZFE en France restent pleinement exploitables sur les corridors Dakar-Bamako et Abidjan-Bamako.
A3: Transport & logistique | B3: Pedretti Distribution | C3: n.d. | D3: n.d. — 12 agences | E3: 390 | F3: 45000000 | G3: Redressement judiciaire | H3: n.d. (décembre 2025) | I3: Aucun repreneur trouvé à l'issue de la période d'observation | J3: Flotte de distribution, 12 agences | K3: https://trans.info/fr/faillites-transport-france-2026-ziegler-pedretti-crise-468940 | L3: Presse spécialisée | M3: 4 | N3: 5 | O3: 4 | P3: 5 | Q3: 5 | R3: 4 | S3: 3 | T3: =IF(COUNT(M3:S3)<7,"",SUMPRODUCT(M3:S3,'Grille Mali'!$C$14:$I$14)) -> 4.45 | U3: =IF(NOT(ISNUMBER(T3)),"",IF(T3>=4,"A — Prioritaire",IF(T3>=3,"B — À étudier",IF(T3>=2,"C — Marginal","D — Non pertinent")))) -> A — Prioritaire | V3: Le réseau d'agences n'est pas transférable, la flotte et l'outillage d'atelier le sont. Vérifier l'âge moyen du parc avant toute offre.
A4: Transport & logistique | B4: Sogran | C4: n.d. | D4: Région de Saint-Étienne (42) | E4: 110 | F4: n.d. | G4: Liquidation judiciaire | H4: n.d. (2026) | I4: Liquidation — transporteur fondé en 1984 | J4: Flotte régionale, atelier de maintenance | K4: https://sgtcf.fr/faillites-de-transporteurs-routiers-en-france-une-annee-2026-qui-demarre-sous-tension/ | L4: Presse syndicale | M4: 4 | N4: 5 | O4: 4 | P4: 5 | Q4: 5 | R4: 4 | S4: 3 | T4: =IF(COUNT(M4:S4)<7,"",SUMPRODUCT(M4:S4,'Grille Mali'!$C$14:$I$14)) -> 4.45 | U4: =IF(NOT(ISNUMBER(T4)),"",IF(T4>=4,"A — Prioritaire",IF(T4>=3,"B — À étudier",IF(T4>=2,"C — Marginal","D — Non pertinent")))) -> A — Prioritaire | V4: Taille adaptée à une première opération pilote : lot de véhicules homogène, atelier de maintenance reprenable en bloc.
A5: Fabrication de machines-outils | B5: Mécanuméric | C5: n.d. | D5: Tarn (81) | E5: n.d. | F5: n.d. | G5: Redressement judiciaire | H5: n.d. (décembre 2024) | I5: Procédure ouverte — impact du recul de l'investissement industriel européen | J5: Équipements de découpe et d'usinage (constructeur) | K5: https://www.machinesproduction.fr/article/mecanumeric-en-redressement-un-passage-oblige-pour-rebondir | L5: Presse spécialisée | M5: 3 | N5: 2 | O5: 1 | P5: 3 | Q5: 2 | R5: 4 | S5: 2 | T5: =IF(COUNT(M5:S5)<7,"",SUMPRODUCT(M5:S5,'Grille Mali'!$C$14:$I$14)) -> 2.4 | U5: =IF(NOT(ISNUMBER(T5)),"",IF(T5>=4,"A — Prioritaire",IF(T5>=3,"B — À étudier",IF(T5>=2,"C — Marginal","D — Non pertinent")))) -> C — Marginal | V5: Transférer une activité de construction de machines-outils au Mali n'est pas réaliste : l'écosystème de sous-traitance nécessaire est absent. En revanche le parc machines interne est reconvertible en atelier de mécanique générale pour la maintenance minière.
A6: Fabrication de machines-outils | B6: Mécanique Gaillonnaise de Précision | C6: 352461883 | D6: Le Val d'Hazey (27940) — Eure | E6: n.d. | F6: n.d. | G6: Redressement judiciaire | H6: 2026-04-12 | I6: Cessation des paiements fixée au 20/03/2026 | J6: Parc machines de mécanique de précision | K6: https://www.procedures-collectives.com/entreprise/352461883-mecanique-gaillonnaise-de-precision/ | L6: Base procédures collectives | M6: 3 | N6: 2 | O6: 1 | P6: 3 | Q6: 2 | R6: 4 | S6: 2 | T6: =IF(COUNT(M6:S6)<7,"",SUMPRODUCT(M6:S6,'Grille Mali'!$C$14:$I$14)) -> 2.4 | U6: =IF(NOT(ISNUMBER(T6)),"",IF(T6>=4,"A — Prioritaire",IF(T6>=3,"B — À étudier",IF(T6>=2,"C — Marginal","D — Non pertinent")))) -> C — Marginal | V6: Seul dossier de l'échantillon avec SIREN confirmé et date de jugement précise. L'intérêt porte sur le parc machines, pas sur l'activité de précision elle-même.
A7: Fabrication de machines-outils | B7: Gallez Industrie | C7: n.d. | D7: Pas-de-Calais (62) | E7: n.d. | F7: n.d. | G7: Cession en procédure collective | H7: n.d. | I7: À confirmer — annonce de cession par mandataire | J7: Sous-traitance mécanique automobile | K7: https://ajilink.fr/secteur-automobile-gallez-industrie-pas-de-calais/ | L7: Faible — à confirmer | M7: 3 | N7: 2 | O7: 1 | P7: 3 | Q7: 2 | R7: 4 | S7: 2 | T7: =IF(COUNT(M7:S7)<7,"",SUMPRODUCT(M7:S7,'Grille Mali'!$C$14:$I$14)) -> 2.4 | U7: =IF(NOT(ISNUMBER(T7)),"",IF(T7>=4,"A — Prioritaire",IF(T7>=3,"B — À étudier",IF(T7>=2,"C — Marginal","D — Non pertinent")))) -> C — Marginal | V7: Rattachement sectoriel à confirmer (mécanique ou plasturgie automobile). Ne pas instruire avant vérification du code APE au registre.
A8: Transformation plastique | B8: Tahe Outdoors France (ex-Bic Sport) | C8: n.d. | D8: Vannes (56) — tribunal de commerce de Vannes | E8: n.d. | F8: n.d. | G8: Redressement judiciaire (demande) | H8: 2026-02-27 | I8: Recherche active d'un repreneur | J8: Site de production de Vannes, technologies de transformation composites et plastiques | K8: https://www.usinenouvelle.com/polymeres-materiaux/materiaux/plastiques-et-composites/ex-bic-sport-le-groupe-tahe-outdoors-france-engage-une-procedure-de-redressement-judiciaire-et-cherche-un-repreneur.GD32GWOJWRCG3GRY622C3CEEWY.html | L8: Presse spécialisée | M8: 4 | N8: 2 | O8: 4 | P8: 4 | Q8: 5 | R8: 4 | S8: 2 | T8: =IF(COUNT(M8:S8)<7,"",SUMPRODUCT(M8:S8,'Grille Mali'!$C$14:$I$14)) -> 3.65 | U8: =IF(NOT(ISNUMBER(T8)),"",IF(T8>=4,"A — Prioritaire",IF(T8>=3,"B — À étudier",IF(T8>=2,"C — Marginal","D — Non pertinent")))) -> B — À étudier | V8: Outillage de transformation polyvalent. Le produit fini (planches de sport nautique) n'a aucun marché malien : l'intérêt porte sur les moules, les presses et le savoir-faire composite, réaffectés à l'emballage ou au BTP.
A9: Transformation plastique | B9: RecyOuest | C9: n.d. | D9: Orne (61) — Normandie | E9: n.d. | F9: n.d. | G9: Liquidation judiciaire | H9: n.d. | I9: 6 M€ de dettes — la direction espère un repreneur | J9: Ligne de régénération de matières plastiques | K9: https://france3-regions.franceinfo.fr/normandie/orne/avec-6-millions-d-euros-de-dettes-l-entreprise-recyouest-placee-en-liquidation-judiciaire-la-directrice-espere-un-repreneur-3191679.html | L9: Presse régionale | M9: 4 | N9: 2 | O9: 4 | P9: 4 | Q9: 5 | R9: 4 | S9: 2 | T9: =IF(COUNT(M9:S9)<7,"",SUMPRODUCT(M9:S9,'Grille Mali'!$C$14:$I$14)) -> 3.65 | U9: =IF(NOT(ISNUMBER(T9)),"",IF(T9>=4,"A — Prioritaire",IF(T9>=3,"B — À étudier",IF(T9>=2,"C — Marginal","D — Non pertinent")))) -> B — À étudier | V9: Cas le plus cohérent avec le contexte malien : une ligne de régénération alimentée par le gisement local de déchets plastiques répond à la fois au besoin en matière première et à un enjeu environnemental urbain à Bamako.
A10: Fabrication de matériel électrique | B10: Groupe Brandt | C10: n.d. | D10: Siège Nanterre (92) — sites Centre-Val de Loire | E10: 700 | F10: n.d. | G10: Liquidation judiciaire | H10: n.d. (2026) | I10: Redressement en octobre puis liquidation prononcée par le TC de Nanterre — 700 emplois supprimés | J10: Lignes d'assemblage d'appareils électroménagers (NAF 27.51Z) | K10: https://www.francebleu.fr/infos/economie-social/groupe-brandt-le-tribunal-prononce-la-liquidation-judiciaire-700-emplois-supprimes-7701700 | L10: Presse nationale | M10: 4 | N10: 3 | O10: 3 | P10: 4 | Q10: 5 | R10: 3 | S10: 2 | T10: =IF(COUNT(M10:S10)<7,"",SUMPRODUCT(M10:S10,'Grille Mali'!$C$14:$I$14)) -> 3.6 | U10: =IF(NOT(ISNUMBER(T10)),"",IF(T10>=4,"A — Prioritaire",IF(T10>=3,"B — À étudier",IF(T10>=2,"C — Marginal","D — Non pertinent")))) -> B — À étudier | V10: Lignes d'assemblage à forte intensité de main-d'oeuvre, donc transférables sur le principe. Réserve majeure : la demande malienne en gros électroménager est étroite et très exposée au délestage.
A11: Fabrication de matériel électrique | B11: Groupe GCK | C11: n.d. | D11: Auvergne-Rhône-Alpes | E11: n.d. | F11: n.d. | G11: Redressement judiciaire | H11: n.d. (2026) | I11: Recherche de repreneur — date limite de dépôt des offres au 19/06/2026 | J11: Technologies de mobilité électrique | K11: https://www.spark-avocats.com/groupe-gck-cherche-repreneur-dans-le-cadre-dun-redressement-judiciaire/ | L11: Cabinet d'avocats | M11: 4 | N11: 3 | O11: 3 | P11: 4 | Q11: 5 | R11: 3 | S11: 2 | T11: =IF(COUNT(M11:S11)<7,"",SUMPRODUCT(M11:S11,'Grille Mali'!$C$14:$I$14)) -> 3.6 | U11: =IF(NOT(ISNUMBER(T11)),"",IF(T11>=4,"A — Prioritaire",IF(T11>=3,"B — À étudier",IF(T11>=2,"C — Marginal","D — Non pertinent")))) -> B — À étudier | V11: Positionnement retrofit et mobilité électrique sans marché malien à court terme. À écarter, sauf intérêt ciblé sur un banc d'essai ou un atelier de bobinage.
A12: Fabrication de médicaments génériques | B12: Ipsomédic | C12: n.d. | D12: Aubagne (13) — Bouches-du-Rhône | E12: 17 | F12: 630483 | G12: Redressement judiciaire | H12: 2025-11-17 | I12: Sursis obtenu jusqu'au 08/01/2026 pour trouver un repreneur | J12: 4 brevets de procédé de production en continu de principes actifs (dont paracétamol) | K12: https://www.lejournaldesentreprises.com/breve/ipsomedic-detenteur-dune-licence-exclusive-pour-la-fabrication-du-paracetamol-en-sursis-jusquen-2133562 | L12: Presse économique | M12: 3 | N12: 2 | O12: 1 | P12: 2 | Q12: 5 | R12: 1 | S12: 2 | T12: =IF(COUNT(M12:S12)<7,"",SUMPRODUCT(M12:S12,'Grille Mali'!$C$14:$I$14)) -> 2.4 | U12: =IF(NOT(ISNUMBER(T12)),"",IF(T12>=4,"A — Prioritaire",IF(T12>=3,"B — À étudier",IF(T12>=2,"C — Marginal","D — Non pertinent")))) -> C — Marginal | V12: Le seul actif réellement stratégique de l'échantillon est immatériel : 4 brevets de production en continu d'API. Un transfert de licence ne suppose ni déplacement de ligne ni requalification de site — voie bien plus rapide qu'une reprise d'usine.
A14: Échantillon non exhaustif, issu de la presse et de bases publiques consultées le 30/08/2026 — voir l'onglet Lisez-moi. Les notes en bleu sont des hypothèses sectorielles reprises de referentiel.py, à ajuster après visite de site.

Sheet Grille Mali
A1: Grille de transférabilité vers le Mali
A2: Notes de 1 à 5 : 5 = configuration la plus favorable au transfert. Les pondérations (bleu) sont modifiables ; leur somme doit rester à 100 %.
A3: Code | B3: Critère | C3: Pondération | D3: Définition et justification
A4: C1 | B4: Intensité main-d'oeuvre | C4: 0.2 | D4: Part du process reposant sur du travail manuel plutôt que sur de l'automatisation. Le Mali offre une main-d'oeuvre abondante et peu coûteuse ; un process automatisé n'y gagne rien.
A5: C2 | B5: Sobriété énergétique | C5: 0.2 | D5: Le réseau d'EDM-SA subit des délestages fréquents et un coût du kWh élevé. Un process électro-intensif en continu (extrusion, four, HVAC de salle blanche) exige une centrale captive — surcoût majeur.
A6: C3 | B6: Simplicité technologique | C6: 0.15 | D6: Niveau de qualification technique exigé par le process. Le vivier malien d'ingénieurs et de techniciens de maintenance industrielle reste étroit sur les métiers de précision.
A7: C4 | B7: Transportabilité des actifs | C7: 0.15 | D7: Aptitude des équipements à être démontés, conteneurisés et remontés. Une presse à injecter se déplace ; une ligne intégrée coulée dans le génie civil, non.
A8: C5 | B8: Marché Mali / AES / UEMOA | C8: 0.15 | D8: Demande locale et régionale adressable. Le Mali reste dans l'UEMOA (franc CFA) mais s'est retiré de la CEDEAO au profit de l'AES — le régime tarifaire applicable est à vérifier dossier par dossier.
A9: C6 | B9: Faiblesse des barrières réglementaires | C9: 0.1 | D9: Certifications à retransférer : BPF/GMP et AMM en pharmacie, marquage CE et normes produit en matériel électrique. Une requalification de site pharmaceutique se compte en années.
A10: C7 | B10: Autonomie en intrants | C10: 0.05 | D10: Dépendance aux matières importées. Le Mali est enclavé : tout intrant transite par les corridors Dakar, Abidjan, Lomé ou Conakry, avec le délai et le coût correspondants.
B11: Total | C11: =SUM(C4:C10) -> 1 | D11: =IF(ROUND(C11,6)=1,"Pondérations cohérentes.","ANOMALIE : la somme des pondérations doit valoir 100 %.") -> Pondérations cohérentes.
B13: Pondérations en ligne (utilisées par les formules de score) | C13: C1 | D13: C2 | E13: C3 | F13: C4 | G13: C5 | H13: C6 | I13: C7
B14: ↳ recopie de la colonne C, ne pas saisir ici | C14: =C4 -> 0.2 | D14: =C5 -> 0.2 | E14: =C6 -> 0.15 | F14: =C7 -> 0.15 | G14: =C8 -> 0.15 | H14: =C9 -> 0.1 | I14: =C10 -> 0.05
A16: Barème de classement
A17: Classe | B17: Seuil | C17: Lecture
A18: A — Prioritaire | B18: Score >= 4,0 | C18: Dossier à instruire en priorité.
A19: B — À étudier | B19: 3,0 <= score < 4,0 | C19: Transfert plausible sous conditions.
A20: C — Marginal | B20: 2,0 <= score < 3,0 | C20: Seuls certains actifs sont pertinents.
A21: D — Non pertinent | B21: Score < 2,0 | C21: Transfert non viable en l'état.
A24: Score moyen par secteur (échantillon sourcé)
A25: Secteur | B25: Nb dossiers | C25: Score moyen | D25: Classe moyenne
A26: Transport & logistique | B26: =SUMPRODUCT(--(TRIM('Cas identifiés'!$A$2:$A$12)=TRIM($A26))) -> 3 | C26: =IFERROR(SUMPRODUCT(--(TRIM('Cas identifiés'!$A$2:$A$12)=TRIM($A26)),'Cas identifiés'!$T$2:$T$12)/$B26,"n.d.") -> 4.45 | D26: =IF(NOT(ISNUMBER($C26)),"n.d.",IF($C26>=4,"A",IF($C26>=3,"B",IF($C26>=2,"C","D")))) -> A
A27: Fabrication de matériel électrique | B27: =SUMPRODUCT(--(TRIM('Cas identifiés'!$A$2:$A$12)=TRIM($A27))) -> 2 | C27: =IFERROR(SUMPRODUCT(--(TRIM('Cas identifiés'!$A$2:$A$12)=TRIM($A27)),'Cas identifiés'!$T$2:$T$12)/$B27,"n.d.") -> 3.6 | D27: =IF(NOT(ISNUMBER($C27)),"n.d.",IF($C27>=4,"A",IF($C27>=3,"B",IF($C27>=2,"C","D")))) -> B
A28: Fabrication de machines-outils | B28: =SUMPRODUCT(--(TRIM('Cas identifiés'!$A$2:$A$12)=TRIM($A28))) -> 3 | C28: =IFERROR(SUMPRODUCT(--(TRIM('Cas identifiés'!$A$2:$A$12)=TRIM($A28)),'Cas identifiés'!$T$2:$T$12)/$B28,"n.d.") -> 2.4 | D28: =IF(NOT(ISNUMBER($C28)),"n.d.",IF($C28>=4,"A",IF($C28>=3,"B",IF($C28>=2,"C","D")))) -> C
A29: Transformation plastique | B29: =SUMPRODUCT(--(TRIM('Cas identifiés'!$A$2:$A$12)=TRIM($A29))) -> 2 | C29: =IFERROR(SUMPRODUCT(--(TRIM('Cas identifiés'!$A$2:$A$12)=TRIM($A29)),'Cas identifiés'!$T$2:$T$12)/$B29,"n.d.") -> 3.65 | D29: =IF(NOT(ISNUMBER($C29)),"n.d.",IF($C29>=4,"A",IF($C29>=3,"B",IF($C29>=2,"C","D")))) -> B
A30: Fabrication de médicaments génériques | B30: =SUMPRODUCT(--(TRIM('Cas identifiés'!$A$2:$A$12)=TRIM($A30))) -> 1 | C30: =IFERROR(SUMPRODUCT(--(TRIM('Cas identifiés'!$A$2:$A$12)=TRIM($A30)),'Cas identifiés'!$T$2:$T$12)/$B30,"n.d.") -> 2.4 | D30: =IF(NOT(ISNUMBER($C30)),"n.d.",IF($C30>=4,"A",IF($C30>=3,"B",IF($C30>=2,"C","D")))) -> C

Sheet Codes NAF
A1: Codes NAF retenus pour le filtrage BODACC
A2: Nomenclature NAF rév. 2. La NAF rév. 3 s'applique aux nouvelles immatriculations depuis 2026 : remapper avant d'exploiter des jugements postérieurs.
A3: Secteur | B3: Code NAF | C3: Libellé
A4: Transport & logistique | B4: 49.20Z | C4: Transports ferroviaires de fret
B5: 49.41A | C5: Transports routiers de fret interurbains
B6: 49.41B | C6: Transports routiers de fret de proximité
B7: 49.41C | C7: Location de camions avec chauffeur
B8: 49.42Z | C8: Services de déménagement
B9: 50.40Z | C9: Transports fluviaux de fret
B10: 52.10A | C10: Entreposage et stockage frigorifique
B11: 52.10B | C11: Entreposage et stockage non frigorifique
B12: 52.24A | C12: Manutention portuaire
B13: 52.24B | C13: Manutention non portuaire
B14: 52.29A | C14: Messagerie, fret express
B15: 52.29B | C15: Affrètement et organisation des transports
A16: Fabrication de matériel électrique | B16: 27.11Z | C16: Fabrication de moteurs, génératrices et transformateurs électriques
B17: 27.12Z | C17: Fabrication de matériel de distribution et de commande électrique
B18: 27.20Z | C18: Fabrication de piles et d'accumulateurs électriques
B19: 27.31Z | C19: Fabrication de câbles de fibres optiques
B20: 27.32Z | C20: Fabrication d'autres fils et câbles électroniques ou électriques
B21: 27.33Z | C21: Fabrication de matériel d'installation électrique
B22: 27.40Z | C22: Fabrication d'appareils d'éclairage électrique
B23: 27.51Z | C23: Fabrication d'appareils électroménagers
B24: 27.52Z | C24: Fabrication d'appareils ménagers non électriques
B25: 27.90Z | C25: Fabrication d'autres matériels électriques
A26: Fabrication de machines-outils | B26: 25.62A | C26: Décolletage
B27: 25.62B | C27: Mécanique industrielle
B28: 28.25Z | C28: Fabrication d'équipements aérauliques et frigorifiques industriels
B29: 28.29B | C29: Fabrication d'autres machines d'usage général
B30: 28.41Z | C30: Fabrication de machines-outils pour le travail des métaux
B31: 28.49Z | C31: Fabrication d'autres machines-outils
B32: 28.99B | C32: Fabrication d'autres machines spécialisées
A33: Transformation plastique | B33: 22.21Z | C33: Fabrication de plaques, feuilles, tubes et profilés en matières plastiques
B34: 22.22Z | C34: Fabrication d'emballages en matières plastiques
B35: 22.23Z | C35: Fabrication d'éléments en matières plastiques pour la construction
B36: 22.29A | C36: Fabrication de pièces techniques à base de matières plastiques
B37: 22.29B | C37: Fabrication de produits de consommation courante en matières plastiques
B38: 38.32Z | C38: Récupération de déchets triés (régénération de matières plastiques)
A39: Fabrication de médicaments génériques | B39: 21.10Z | C39: Fabrication de produits pharmaceutiques de base (principes actifs)
B40: 21.20Z | C40: Fabrication de préparations pharmaceutiques (formes sèches, liquides)
...

Sheet Modèle de saisie
A1: Secteur | B1: Raison sociale | C1: SIREN | D1: Localisation | E1: Effectif | F1: CA (EUR) | G1: Procédure | H1: Date jugement | I1: Statut / échéance | J1: Actifs industriels | K1: Source (URL) | L1: Fiabilité source | M1: C1 | N1: C2 | O1: C3 | P1: C4 | Q1: C5 | R1: C6 | S1: C7 | T1: Score /5 | U1: Classe | V1: Commentaire transfert Mali
A2: Transformation plastique | B2: EXEMPLE — Plastiques du Rhône SAS | C2: 812345678 | D2: Vénissieux (69) — TC de Lyon | E2: 84 | F2: 11200000 | G2: Redressement judiciaire | H2: 2026-07-15 | I2: Offres à déposer avant le 15/11/2026 | J2: 12 presses à injecter 80-450 t, 2 extrudeuses, atelier moules | K2: https://www.bodacc.fr/annonce/exemple | L2: BODACC — jugement publié | M2: 4 | N2: 2 | O2: 4 | P2: 4 | Q2: 5 | R2: 4 | S2: 2 | T2: =IF(COUNT(M2:S2)<7,"",SUMPRODUCT(M2:S2,'Grille Mali'!$C$14:$I$14)) -> 3.65 | U2: =IF(NOT(ISNUMBER(T2)),"",IF(T2>=4,"A — Prioritaire",IF(T2>=3,"B — À étudier",IF(T2>=2,"C — Marginal","D — Non pertinent")))) -> B — À étudier | V2: EXEMPLE — ligne fictive de démonstration du format attendu. À supprimer avant exploitation.
T3: =IF(COUNT(M3:S3)<7,"",SUMPRODUCT(M3:S3,'Grille Mali'!$C$14:$I$14)) | U3: =IF(NOT(ISNUMBER(T3)),"",IF(T3>=4,"A — Prioritaire",IF(T3>=3,"B — À étudier",IF(T3>=2,"C — Marginal","D — Non pertinent"))))
T4: =IF(COUNT(M4:S4)<7,"",SUMPRODUCT(M4:S4,'Grille Mali'!$C$14:$I$14)) | U4: =IF(NOT(ISNUMBER(T4)),"",IF(T4>=4,"A — Prioritaire",IF(T4>=3,"B — À étudier",IF(T4>=2,"C — Marginal","D — Non pertinent"))))
T5: =IF(COUNT(M5:S5)<7,"",SUMPRODUCT(M5:S5,'Grille Mali'!$C$14:$I$14)) | U5: =IF(NOT(ISNUMBER(T5)),"",IF(T5>=4,"A — Prioritaire",IF(T5>=3,"B — À étudier",IF(T5>=2,"C — Marginal","D — Non pertinent"))))
T6: =IF(COUNT(M6:S6)<7,"",SUMPRODUCT(M6:S6,'Grille Mali'!$C$14:$I$14)) | U6: =IF(NOT(ISNUMBER(T6)),"",IF(T6>=4,"A — Prioritaire",IF(T6>=3,"B — À étudier",IF(T6>=2,"C — Marginal","D — Non pertinent"))))
T7: =IF(COUNT(M7:S7)<7,"",SUMPRODUCT(M7:S7,'Grille Mali'!$C$14:$I$14)) | U7: =IF(NOT(ISNUMBER(T7)),"",IF(T7>=4,"A — Prioritaire",IF(T7>=3,"B — À étudier",IF(T7>=2,"C — Marginal","D — Non pertinent"))))
T8: =IF(COUNT(M8:S8)<7,"",SUMPRODUCT(M8:S8,'Grille Mali'!$C$14:$I$14)) | U8: =IF(NOT(ISNUMBER(T8)),"",IF(T8>=4,"A — Prioritaire",IF(T8>=3,"B — À étudier",IF(T8>=2,"C — Marginal","D — Non pertinent"))))
T9: =IF(COUNT(M9:S9)<7,"",SUMPRODUCT(M9:S9,'Grille Mali'!$C$14:$I$14)) | U9: =IF(NOT(ISNUMBER(T9)),"",IF(T9>=4,"A — Prioritaire",IF(T9>=3,"B — À étudier",IF(T9>=2,"C — Marginal","D — Non pertinent"))))
T10: =IF(COUNT(M10:S10)<7,"",SUMPRODUCT(M10:S10,'Grille Mali'!$C$14:$I$14)) | U10: =IF(NOT(ISNUMBER(T10)),"",IF(T10>=4,"A — Prioritaire",IF(T10>=3,"B — À étudier",IF(T10>=2,"C — Marginal","D — Non pertinent"))))
T11: =IF(COUNT(M11:S11)<7,"",SUMPRODUCT(M11:S11,'Grille Mali'!$C$14:$I$14)) | U11: =IF(NOT(ISNUMBER(T11)),"",IF(T11>=4,"A — Prioritaire",IF(T11>=3,"B — À étudier",IF(T11>=2,"C — Marginal","D — Non pertinent"))))
T12: =IF(COUNT(M12:S12)<7,"",SUMPRODUCT(M12:S12,'Grille Mali'!$C$14:$I$14)) | U12: =IF(NOT(ISNUMBER(T12)),"",IF(T12>=4,"A — Prioritaire",IF(T12>=3,"B — À étudier",IF(T12>=2,"C — Marginal","D — Non pertinent"))))
T13: =IF(COUNT(M13:S13)<7,"",SUMPRODUCT(M13:S13,'Grille Mali'!$C$14:$I$14)) | U13: =IF(NOT(ISNUMBER(T13)),"",IF(T13>=4,"A — Prioritaire",IF(T13>=3,"B — À étudier",IF(T13>=2,"C — Marginal","D — Non pertinent"))))
T14: =IF(COUNT(M14:S14)<7,"",SUMPRODUCT(M14:S14,'Grille Mali'!$C$14:$I$14)) | U14: =IF(NOT(ISNUMBER(T14)),"",IF(T14>=4,"A — Prioritaire",IF(T14>=3,"B — À étudier",IF(T14>=2,"C — Marginal","D — Non pertinent"))))
... T32: =IF(COUNT(M32:S32)<7,"",SUMPRODUCT(M32:S32,'Grille Mali'!$C$14:$I$14)) | U32: =IF(NOT(ISNUMBER(T32)),"",IF(T32>=4,"A — Prioritaire",IF(T32>=3,"B — À étudier",IF(T32>=2,"C — Marginal","D — Non pertinent"))))
A35: MODE D'EMPLOI — Saisir uniquement les cellules bleues. Les 7 colonnes C1 à C7 attendent une note de 1 à 5 (5 = le plus favorable au transfert) ; passer la souris sur l'en-tête d'une colonne pour en lire la définition. Les colonnes Score et Classe sont des formules : ne pas les écraser. Le score reste vide tant que les 7 notes ne sont pas renseignées.
